Workbook

Sheet Pagamentos
A1: BOLÃO DA COPA 2026
A4: Participantes | B4: Pago
A5: Alex | B5: Ok
A6: Bonfim | B6: Ok
A7: Christian | B7: Ok
A8: Daniel | B8: Ok
A9: Douglas | B9: Ok
A10: Dunga | B10: Ok
A11: Gabriel | B11: Ok
A12: Gustavo | B12: Ok
A13: Gustavo Lima | B13: Ok
A14: Heitor | B14: Ok
A15: Leonardo | B15: Ok
... A20: Sanches | B20: Ok

Sheet Apuração
A1: APURAÇÃO — RANKING DO BOLÃO COPA 2026
A3: # | B3: Participante | C3: Acertos | D3: Pontos | E3: Posição | I3: Pontos por acerto
A4: =ROW()-3 -> 1 | B4: Alex | C4: {=SUMPRODUCT((#REF!<>"")*(INDEX(#REF!,0,$A4)=#REF!))} -> #REF! | D4: =C4*$J$4 -> #REF! | E4: =RANK(D4,$D$4:$D$17) -> #REF! | I4: Por acerto | J4: 1
A5: =ROW()-3 -> 2 | B5: Bonfim | C5: {=SUMPRODUCT((#REF!<>"")*(INDEX(#REF!,0,$A5)=#REF!))} -> #REF! | D5: =C5*$J$4 -> #REF! | E5: =RANK(D5,$D$4:$D$17) -> #REF!
A6: =ROW()-3 -> 3 | B6: Christian | C6: {=SUMPRODUCT((#REF!<>"")*(INDEX(#REF!,0,$A6)=#REF!))} -> #REF! | D6: =C6*$J$4 -> #REF! | E6: =RANK(D6,$D$4:$D$17) -> #REF!
A7: =ROW()-3 -> 4 | B7: Daniel | C7: {=SUMPRODUCT((#REF!<>"")*(INDEX(#REF!,0,$A7)=#REF!))} -> #REF! | D7: =C7*$J$4 -> #REF! | E7: =RANK(D7,$D$4:$D$17) -> #REF! | I7: Como funciona
A8: =ROW()-3 -> 5 | B8: Douglas | C8: {=SUMPRODUCT((#REF!<>"")*(INDEX(#REF!,0,$A8)=#REF!))} -> #REF! | D8: =C8*$J$4 -> #REF! | E8: =RANK(D8,$D$4:$D$17) -> #REF! | I8: Preencha a coluna 'Result.' na aba de palpites (A/E/B). O ranking atualiza sozinho.
A9: =ROW()-3 -> 6 | B9: Dunga | C9: {=SUMPRODUCT((#REF!<>"")*(INDEX(#REF!,0,$A9)=#REF!))} -> #REF! | D9: =C9*$J$4 -> #REF! | E9: =RANK(D9,$D$4:$D$17) -> #REF!
A10: =ROW()-3 -> 7 | B10: Gabriel | C10: {=SUMPRODUCT((#REF!<>"")*(INDEX(#REF!,0,$A10)=#REF!))} -> #REF! | D10: =C10*$J$4 -> #REF! | E10: =RANK(D10,$D$4:$D$17) -> #REF!
A11: =ROW()-3 -> 8 | B11: Gustavo | C11: {=SUMPRODUCT((#REF!<>"")*(INDEX(#REF!,0,$A11)=#REF!))} -> #REF! | D11: =C11*$J$4 -> #REF! | E11: =RANK(D11,$D$4:$D$17) -> #REF!
A12: =ROW()-3 -> 9 | B12: Gustavo Lima | C12: {=SUMPRODUCT((#REF!<>"")*(INDEX(#REF!,0,$A12)=#REF!))} -> #REF! | D12: =C12*$J$4 -> #REF! | E12: =RANK(D12,$D$4:$D$17) -> #REF!
A13: =ROW()-3 -> 10 | B13: Heitor | C13: {=SUMPRODUCT((#REF!<>"")*(INDEX(#REF!,0,$A13)=#REF!))} -> #REF! | D13: =C13*$J$4 -> #REF! | E13: =RANK(D13,$D$4:$D$17) -> #REF!
A14: =ROW()-3 -> 11 | B14: Leonardo | C14: {=SUMPRODUCT((#REF!<>"")*(INDEX(#REF!,0,$A14)=#REF!))} -> #REF! | D14: =C14*$J$4 -> #REF! | E14: =RANK(D14,$D$4:$D$17) -> #REF!
A15: =ROW()-3 -> 12 | B15: Patrick | C15: {=SUMPRODUCT((#REF!<>"")*(INDEX(#REF!,0,$A15)=#REF!))} -> #REF! | D15: =C15*$J$4 -> #REF! | E15: =RANK(D15,$D$4:$D$17) -> #REF!
A16: =ROW()-3 -> 13 | B16: Rasta | C16: {=SUMPRODUCT((#REF!<>"")*(INDEX(#REF!,0,$A16)=#REF!))} -> #REF! | D16: =C16*$J$4 -> #REF! | E16: =RANK(D16,$D$4:$D$17) -> #REF!
A17: =ROW()-3 -> 14 | B17: Renan | C17: {=SUMPRODUCT((#REF!<>"")*(INDEX(#REF!,0,$A17)=#REF!))} -> #REF! | D17: =C17*$J$4 -> #REF! | E17: =RANK(D17,$D$4:$D$17) -> #REF!

Sheet ORGANIZAÇÃO
A1: DATAS | B1: CONFRONTOS | C1: TIME A | D1: TIME B | E1: PLACAR | G1: Alex | H1: Bonfim | I1: Christian | J1: Cleiton | K1: Daniel | L1: David | M1: Douglas | N1: Dunga | O1: Felipe | P1: Gabriel | Q1: Giliarde | R1: Gustavo | S1: Gustavo Lima | T1: Heitor | U1: Juninho | V1: Leonardo | W1: Patrick | X1: Rasta | Y1: Renan | Z1: Sanches | AA1: Gols A | AB1: Gols B | AC1: RESULTADO
A2: 46184 | B2: México x África do Sul | C2: =TRIM(LEFT(B2,FIND(" x ",B2)-1)) -> México | D2: =TRIM(MID(B2,FIND(" x ",B2)+3,100)) -> África do Sul | E2: 2x0 | G2: A | H2: B | I2: A | J2: A | K2: A | L2: A | M2: A | N2: A | O2: A | P2: A | Q2: A | R2: E | S2: A | T2: A | U2: A | V2: A | W2: E | X2: B | Y2: A | Z2: A | AA2: =IFERROR(VALUE(TRIM(LEFT($E2,SEARCH("x",$E2)-1))),"") -> 2 | AB2: =IFERROR(VALUE(TRIM(MID($E2,SEARCH("x",$E2)+1,10))),"") -> 0 | AC2: =IF(OR($AA2="",$AB2=""),"",IF($AA2>$AB2,"A",IF($AA2<$AB2,"B","E"))) -> A
B3: Coreia do Sul x Tchéquia | C3: =TRIM(LEFT(B3,FIND(" x ",B3)-1)) -> Coreia do Sul | D3: =TRIM(MID(B3,FIND(" x ",B3)+3,100)) -> Tchéquia | E3: 2x1 | G3: E | H3: A | I3: A | J3: A | K3: A | L3: A | M3: A | N3: A | O3: B | P3: B | Q3: B | R3: A | S3: E | T3: B | U3: E | V3: A | W3: A | X3: A | Y3: A | Z3: B | AA3: =IFERROR(VALUE(TRIM(LEFT($E3,SEARCH("x",$E3)-1))),"") -> 2 | AB3: =IFERROR(VALUE(TRIM(MID($E3,SEARCH("x",$E3)+1,10))),"") -> 1 | AC3: =IF(OR($AA3="",$AB3=""),"",IF($AA3>$AB3,"A",IF($AA3<$AB3,"B","E"))) -> A
A4: 46185 | B4: Canadá x Bósnia e Herzeg. | C4: =TRIM(LEFT(B4,FIND(" x ",B4)-1)) -> Canadá | D4: =TRIM(MID(B4,FIND(" x ",B4)+3,100)) -> Bósnia e Herzeg. | E4: 1x1 | G4: A | H4: E | I4: B | J4: E | K4: A | L4: A | M4: A | N4: A | O4: A | P4: A | Q4: A | R4: A | S4: A | T4: B | U4: A | V4: A | W4: A | X4: A | Y4: B | Z4: B | AA4: =IFERROR(VALUE(TRIM(LEFT($E4,SEARCH("x",$E4)-1))),"") -> 1 | AB4: =IFERROR(VALUE(TRIM(MID($E4,SEARCH("x",$E4)+1,10))),"") -> 1 | AC4: =IF(OR($AA4="",$AB4=""),"",IF($AA4>$AB4,"A",IF($AA4<$AB4,"B","E"))) -> E
B5: Estados Unidos x Paraguai | C5: =TRIM(LEFT(B5,FIND(" x ",B5)-1)) -> Estados Unidos | D5: =TRIM(MID(B5,FIND(" x ",B5)+3,100)) -> Paraguai | E5: 4x1 | G5: B | H5: B | I5: B | J5: A | K5: E | L5: A | M5: B | N5: A | O5: B | P5: A | Q5: E | R5: B | S5: B | T5: E | U5: A | V5: B | W5: A | X5: B | Y5: B | Z5: A | AA5: =IFERROR(VALUE(TRIM(LEFT($E5,SEARCH("x",$E5)-1))),"") -> 4 | AB5: =IFERROR(VALUE(TRIM(MID($E5,SEARCH("x",$E5)+1,10))),"") -> 1 | AC5: =IF(OR($AA5="",$AB5=""),"",IF($AA5>$AB5,"A",IF($AA5<$AB5,"B","E"))) -> A
A6: 46186 | B6: Catar x Suíça | C6: =TRIM(LEFT(B6,FIND(" x ",B6)-1)) -> Catar | D6: =TRIM(MID(B6,FIND(" x ",B6)+3,100)) -> Suíça | E6: 1x1 | G6: B | H6: B | I6: B | J6: B | K6: B | L6: B | M6: B | N6: B | O6: B | P6: B | Q6: A | R6: B | S6: B | T6: B | U6: B | V6: B | W6: B | X6: B | Y6: B | Z6: B | AA6: =IFERROR(VALUE(TRIM(LEFT($E6,SEARCH("x",$E6)-1))),"") -> 1 | AB6: =IFERROR(VALUE(TRIM(MID($E6,SEARCH("x",$E6)+1,10))),"") -> 1 | AC6: =IF(OR($AA6="",$AB6=""),"",IF($AA6>$AB6,"A",IF($AA6<$AB6,"B","E"))) -> E
B7: Brasil x Marrocos | C7: =TRIM(LEFT(B7,FIND(" x ",B7)-1)) -> Brasil | D7: =TRIM(MID(B7,FIND(" x ",B7)+3,100)) -> Marrocos | E7: 1x1 | G7: A | H7: A | I7: A | J7: B | K7: A | L7: A | M7: A | N7: E | O7: E | P7: A | Q7: A | R7: A | S7: A | T7: A | U7: A | V7: A | W7: A | X7: A | Y7: A | Z7: A | AA7: =IFERROR(VALUE(TRIM(LEFT($E7,SEARCH("x",$E7)-1))),"") -> 1 | AB7: =IFERROR(VALUE(TRIM(MID($E7,SEARCH("x",$E7)+1,10))),"") -> 1 | AC7: =IF(OR($AA7="",$AB7=""),"",IF($AA7>$AB7,"A",IF($AA7<$AB7,"B","E"))) -> E
B8: Haiti x Escócia | C8: =TRIM(LEFT(B8,FIND(" x ",B8)-1)) -> Haiti | D8: =TRIM(MID(B8,FIND(" x ",B8)+3,100)) -> Escócia | E8: 0x1 | G8: A | H8: A | I8: B | J8: B | K8: B | L8: B | M8: B | N8: B | O8: B | P8: B | Q8: B | R8: B | S8: B | T8: B | U8: B | V8: B | W8: B | X8: A | Y8: B | Z8: B | AA8: =IFERROR(VALUE(TRIM(LEFT($E8,SEARCH("x",$E8)-1))),"") -> 0 | AB8: =IFERROR(VALUE(TRIM(MID($E8,SEARCH("x",$E8)+1,10))),"") -> 1 | AC8: =IF(OR($AA8="",$AB8=""),"",IF($AA8>$AB8,"A",IF($AA8<$AB8,"B","E"))) -> B
B9: Austrália x Turquia | C9: =TRIM(LEFT(B9,FIND(" x ",B9)-1)) -> Austrália | D9: =TRIM(MID(B9,FIND(" x ",B9)+3,100)) -> Turquia | E9: 2x0 | G9: A | H9: B | I9: B | J9: B | K9: B | L9: B | M9: B | N9: B | O9: B | P9: B | Q9: A | R9: A | S9: B | T9: B | U9: B | V9: B | W9: B | X9: A | Y9: B | Z9: B | AA9: =IFERROR(VALUE(TRIM(LEFT($E9,SEARCH("x",$E9)-1))),"") -> 2 | AB9: =IFERROR(VALUE(TRIM(MID($E9,SEARCH("x",$E9)+1,10))),"") -> 0 | AC9: =IF(OR($AA9="",$AB9=""),"",IF($AA9>$AB9,"A",IF($AA9<$AB9,"B","E"))) -> A
A10: 46187 | B10: Alemanha x Curaçao | C10: =TRIM(LEFT(B10,FIND(" x ",B10)-1)) -> Alemanha | D10: =TRIM(MID(B10,FIND(" x ",B10)+3,100)) -> Curaçao | E10: 7x1 | G10: A | H10: A | I10: A | J10: A | K10: A | L10: A | M10: A | N10: A | O10: A | P10: A | Q10: A | R10: A | S10: A | T10: A | U10: A | V10: A | W10: A | Y10: A | Z10: A | AA10: =IFERROR(VALUE(TRIM(LEFT($E10,SEARCH("x",$E10)-1))),"") -> 7 | AB10: =IFERROR(VALUE(TRIM(MID($E10,SEARCH("x",$E10)+1,10))),"") -> 1 | AC10: =IF(OR($AA10="",$AB10=""),"",IF($AA10>$AB10,"A",IF($AA10<$AB10,"B","E"))) -> A
B11: Costa do Marfim x Equador | C11: =TRIM(LEFT(B11,FIND(" x ",B11)-1)) -> Costa do Marfim | D11: =TRIM(MID(B11,FIND(" x ",B11)+3,100)) -> Equador | E11: 1x0 | G11: A | H11: E | I11: A | J11: E | K11: E | L11: B | M11: E | N11: B | O11: B | P11: A | Q11: A | R11: E | S11: B | T11: B | U11: A | V11: E | W11: B | X11: B | Y11: A | Z11: B | AA11: =IFERROR(VALUE(TRIM(LEFT($E11,SEARCH("x",$E11)-1))),"") -> 1 | AB11: =IFERROR(VALUE(TRIM(MID($E11,SEARCH("x",$E11)+1,10))),"") -> 0 | AC11: =IF(OR($AA11="",$AB11=""),"",IF($AA11>$AB11,"A",IF($AA11<$AB11,"B","E"))) -> A
B12: Países Baixos x Japão | C12: =TRIM(LEFT(B12,FIND(" x ",B12)-1)) -> Países Baixos | D12: =TRIM(MID(B12,FIND(" x ",B12)+3,100)) -> Japão | E12: 2x2 | G12: A | H12: B | I12: E | J12: A | K12: B | L12: A | M12: A | N12: A | O12: A | P12: B | Q12: B | R12: A | S12: A | T12: E | U12: B | V12: B | W12: E | X12: A | Y12: A | Z12: A | AA12: =IFERROR(VALUE(TRIM(LEFT($E12,SEARCH("x",$E12)-1))),"") -> 2 | AB12: =IFERROR(VALUE(TRIM(MID($E12,SEARCH("x",$E12)+1,10))),"") -> 2 | AC12: =IF(OR($AA12="",$AB12=""),"",IF($AA12>$AB12,"A",IF($AA12<$AB12,"B","E"))) -> E
B13: Suécia x Tunísia | C13: =TRIM(LEFT(B13,FIND(" x ",B13)-1)) -> Suécia | D13: =TRIM(MID(B13,FIND(" x ",B13)+3,100)) -> Tunísia | E13: 5x1 | G13: E | H13: A | I13: A | J13: A | K13: A | L13: B | M13: A | N13: A | O13: E | P13: A | Q13: B | R13: E | S13: A | T13: A | U13: A | V13: E | W13: A | X13: A | Y13: A | Z13: A | AA13: =IFERROR(VALUE(TRIM(LEFT($E13,SEARCH("x",$E13)-1))),"") -> 5 | AB13: =IFERROR(VALUE(TRIM(MID($E13,SEARCH("x",$E13)+1,10))),"") -> 1 | AC13: =IF(OR($AA13="",$AB13=""),"",IF($AA13>$AB13,"A",IF($AA13<$AB13,"B","E"))) -> A
A14: 46188 | B14: Bélgica x Egito | C14: =TRIM(LEFT(B14,FIND(" x ",B14)-1)) -> Bélgica | D14: =TRIM(MID(B14,FIND(" x ",B14)+3,100)) -> Egito | E14: 1x1 | G14: A | H14: A | I14: A | J14: E | K14: A | L14: A | M14: A | N14: A | O14: A | P14: A | Q14: A | R14: A | S14: A | T14: A | U14: A | V14: A | W14: A | X14: A | Y14: A | Z14: A | AA14: =IFERROR(VALUE(TRIM(LEFT($E14,SEARCH("x",$E14)-1))),"") -> 1 | AB14: =IFERROR(VALUE(TRIM(MID($E14,SEARCH("x",$E14)+1,10))),"") -> 1 | AC14: =IF(OR($AA14="",$AB14=""),"",IF($AA14>$AB14,"A",IF($AA14<$AB14,"B","E"))) -> E
B15: Irã x Nova Zelândia | C15: =TRIM(LEFT(B15,FIND(" x ",B15)-1)) -> Irã | D15: =TRIM(MID(B15,FIND(" x ",B15)+3,100)) -> Nova Zelândia | E15: 2x2 | G15: E | H15: E | I15: A | J15: A | K15: E | L15: E | M15: A | N15: A | O15: A | P15: E | Q15: A | R15: E | S15: B | T15: A | U15: A | V15: A | W15: A | X15: A | Y15: B | Z15: A | AA15: =IFERROR(VALUE(TRIM(LEFT($E15,SEARCH("x",$E15)-1))),"") -> 2 | AB15: =IFERROR(VALUE(TRIM(MID($E15,SEARCH("x",$E15)+1,10))),"") -> 2 | AC15: =IF(OR($AA15="",$AB15=""),"",IF($AA15>$AB15,"A",IF($AA15<$AB15,"B","E"))) -> E
B16: Espanha x Cabo Verde | C16: =TRIM(LEFT(B16,FIND(" x ",B16)-1)) -> Espanha | D16: =TRIM(MID(B16,FIND(" x ",B16)+3,100)) -> Cabo Verde | E16: 0x0 | G16: A | H16: A | I16: A | J16: A | K16: A | L16: A | M16: A | N16: A | O16: A | P16: A | Q16: A | R16: A | S16: A | T16: A | U16: A | V16: A | W16: A | X16: A | Y16: A | Z16: A | AA16: =IFERROR(VALUE(TRIM(LEFT($E16,SEARCH("x",$E16)-1))),"") -> 0 | AB16: =IFERROR(VALUE(TRIM(MID($E16,SEARCH("x",$E16)+1,10))),"") -> 0 | AC16: =IF(OR($AA16="",$AB16=""),"",IF($AA16>$AB16,"A",IF($AA16<$AB16,"B","E"))) -> E
B17: Arábia Saudita x Uruguai | C17: =TRIM(LEFT(B17,FIND(" x ",B17)-1)) -> Arábia Saudita | D17: =TRIM(MID(B17,FIND(" x ",B17)+3,100)) -> Uruguai | E17: 1x1 | G17: B | H17: B | I17: B | J17: B | K17: B | L17: B | M17: B | N17: B | O17: B | P17: B | Q17: A | R17: B | S17: B | T17: B | U17: B | V17: B | W17: B | X17: B | Y17: B | Z17: B | AA17: =IFERROR(VALUE(TRIM(LEFT($E17,SEARCH("x",$E17)-1))),"") -> 1 | AB17: =IFERROR(VALUE(TRIM(MID($E17,SEARCH("x",$E17)+1,10))),"") -> 1 | AC17: =IF(OR($AA17="",$AB17=""),"",IF($AA17>$AB17,"A",IF($AA17<$AB17,"B","E"))) -> E
A18: 46189 | B18: França x Senegal | C18: =TRIM(LEFT(B18,FIND(" x ",B18)-1)) -> França | D18: =TRIM(MID(B18,FIND(" x ",B18)+3,100)) -> Senegal | E18: 3x1 | G18: A | H18: A | I18: A | J18: A | K18: A | L18: A | M18: A | N18: A | O18: A | P18: A | Q18: A | R18: A | S18: A | T18: A | U18: A | V18: A | W18: A | X18: A | Y18: A | Z18: A | AA18: =IFERROR(VALUE(TRIM(LEFT($E18,SEARCH("x",$E18)-1))),"") -> 3 | AB18: =IFERROR(VALUE(TRIM(MID($E18,SEARCH("x",$E18)+1,10))),"") -> 1 | AC18: =IF(OR($AA18="",$AB18=""),"",IF($AA18>$AB18,"A",IF($AA18<$AB18,"B","E"))) -> A
B19: Iraque x Noruega | C19: =TRIM(LEFT(B19,FIND(" x ",B19)-1)) -> Iraque | D19: =TRIM(MID(B19,FIND(" x ",B19)+3,100)) -> Noruega | E19: 1x4 | G19: E | H19: B | I19: B | J19: B | K19: B | L19: E | M19: B | N19: B | O19: E | P19: B | Q19: A | R19: E | S19: B | T19: B | U19: B | V19: B | W19: B | X19: B | Y19: B | Z19: A | AA19: =IFERROR(VALUE(TRIM(LEFT($E19,SEARCH("x",$E19)-1))),"") -> 1 | AB19: =IFERROR(VALUE(TRIM(MID($E19,SEARCH("x",$E19)+1,10))),"") -> 4 | AC19: =IF(OR($AA19="",$AB19=""),"",IF($AA19>$AB19,"A",IF($AA19<$AB19,"B","E"))) -> B
B20: Argentina x Argélia | C20: =TRIM(LEFT(B20,FIND(" x ",B20)-1)) -> Argentina | D20: =TRIM(MID(B20,FIND(" x ",B20)+3,100)) -> Argélia | E20: 3x0 | G20: A | H20: A | I20: A | J20: A | K20: A | L20: A | M20: A | N20: A | O20: A | P20: A | Q20: A | R20: A | S20: A | T20: E | U20: A | V20: A | W20: A | X20: A | Y20: A | Z20: A | AA20: =IFERROR(VALUE(TRIM(LEFT($E20,SEARCH("x",$E20)-1))),"") -> 3 | AB20: =IFERROR(VALUE(TRIM(MID($E20,SEARCH("x",$E20)+1,10))),"") -> 0 | AC20: =IF(OR($AA20="",$AB20=""),"",IF($AA20>$AB20,"A",IF($AA20<$AB20,"B","E"))) -> A
B21: Áustria x Jordânia | C21: =TRIM(LEFT(B21,FIND(" x ",B21)-1)) -> Áustria | D21: =TRIM(MID(B21,FIND(" x ",B21)+3,100)) -> Jordânia | E21: 3x1 | G21: A | H21: E | I21: E | J21: A | K21: A | L21: A | M21: A | N21: A | O21: A | P21: A | Q21: A | R21: A | S21: E | T21: A | U21: A | V21: E | W21: A | X21: E | Y21: A | Z21: A | AA21: =IFERROR(VALUE(TRIM(LEFT($E21,SEARCH("x",$E21)-1))),"") -> 3 | AB21: =IFERROR(VALUE(TRIM(MID($E21,SEARCH("x",$E21)+1,10))),"") -> 1 | AC21: =IF(OR($AA21="",$AB21=""),"",IF($AA21>$AB21,"A",IF($AA21<$AB21,"B","E"))) -> A
A22: 46190 | B22: Portugal x Rep. Dem. Congo | C22: =TRIM(LEFT(B22,FIND(" x ",B22)-1)) -> Portugal | D22: =TRIM(MID(B22,FIND(" x ",B22)+3,100)) -> Rep. Dem. Congo | E22: 1x1 | G22: A | H22: A | I22: A | J22: A | K22: A | L22: A | M22: A | N22: A | O22: A | P22: A | Q22: A | R22: A | S22: A | T22: A | U22: A | V22: A | W22: A | X22: A | Y22: A | Z22: A | AA22: =IFERROR(VALUE(TRIM(LEFT($E22,SEARCH("x",$E22)-1))),"") -> 1 | AB22: =IFERROR(VALUE(TRIM(MID($E22,SEARCH("x",$E22)+1,10))),"") -> 1 | AC22: =IF(OR($AA22="",$AB22=""),"",IF($AA22>$AB22,"A",IF($AA22<$AB22,"B","E"))) -> E
B23: Uzbequistão x Colômbia | C23: =TRIM(LEFT(B23,FIND(" x ",B23)-1)) -> Uzbequistão | D23: =TRIM(MID(B23,FIND(" x ",B23)+3,100)) -> Colômbia | E23: 1x3 | G23: B | H23: B | I23: B | J23: E | K23: B | L23: B | M23: B | N23: B | O23: B | P23: B | Q23: B | R23: B | S23: B | T23: B | U23: B | V23: B | W23: B | X23: B | Y23: B | Z23: B | AA23: =IFERROR(VALUE(TRIM(LEFT($E23,SEARCH("x",$E23)-1))),"") -> 1 | AB23: =IFERROR(VALUE(TRIM(MID($E23,SEARCH("x",$E23)+1,10))),"") -> 3 | AC23: =IF(OR($AA23="",$AB23=""),"",IF($AA23>$AB23,"A",IF($AA23<$AB23,"B","E"))) -> B
B24: Inglaterra x Croácia | C24: =TRIM(LEFT(B24,FIND(" x ",B24)-1)) -> Inglaterra | D24: =TRIM(MID(B24,FIND(" x ",B24)+3,100)) -> Croácia | E24: 4x2 | G24: A | H24: A | I24: A | J24: A | K24: A | L24: A | M24: A | N24: A | O24: E | P24: A | Q24: B | R24: A | S24: B | T24: E | U24: A | V24: A | W24: E | X24: A | Y24: E | Z24: B | AA24: =IFERROR(VALUE(TRIM(LEFT($E24,SEARCH("x",$E24)-1))),"") -> 4 | AB24: =IFERROR(VALUE(TRIM(MID($E24,SEARCH("x",$E24)+1,10))),"") -> 2 | AC24: =IF(OR($AA24="",$AB24=""),"",IF($AA24>$AB24,"A",IF($AA24<$AB24,"B","E"))) -> A
B25: Gana x Panamá | C25: =TRIM(LEFT(B25,FIND(" x ",B25)-1)) -> Gana | D25: =TRIM(MID(B25,FIND(" x ",B25)+3,100)) -> Panamá | E25: 1x0 | G25: A | H25: A | I25: A | J25: E | K25: A | L25: E | M25: A | N25: A | O25: A | P25: A | Q25: A | R25: A | S25: E | T25: A | U25: A | V25: A | W25: A | X25: A | Y25: A | Z25: A | AA25: =IFERROR(VALUE(TRIM(LEFT($E25,SEARCH("x",$E25)-1))),"") -> 1 | AB25: =IFERROR(VALUE(TRIM(MID($E25,SEARCH("x",$E25)+1,10))),"") -> 0 | AC25: =IF(OR($AA25="",$AB25=""),"",IF($AA25>$AB25,"A",IF($AA25<$AB25,"B","E"))) -> A
A26: 46191 | B26: Tchéquia x África do Sul | C26: =TRIM(LEFT(B26,FIND(" x ",B26)-1)) -> Tchéquia | D26: =TRIM(MID(B26,FIND(" x ",B26)+3,100)) -> África do Sul | E26: 1x1 | G26: A | H26: A | I26: A | J26: A | K26: A | L26: A | M26: A | N26: A | O26: A | P26: A | Q26: A | R26: E | S26: E | T26: A | U26: A | V26: A | W26: B | X26: B | Y26: A | Z26: A | AA26: =IFERROR(VALUE(TRIM(LEFT($E26,SEARCH("x",$E26)-1))),"") -> 1 | AB26: =IFERROR(VALUE(TRIM(MID($E26,SEARCH("x",$E26)+1,10))),"") -> 1 | AC26: =IF(OR($AA26="",$AB26=""),"",IF($AA26>$AB26,"A",IF($AA26<$AB26,"B","E"))) -> E
B27: México x Coreia do Sul | C27: =TRIM(LEFT(B27,FIND(" x ",B27)-1)) -> México | D27: =TRIM(MID(B27,FIND(" x ",B27)+3,100)) -> Coreia do Sul | E27: 1x0 | G27: A | H27: A | I27: B | J27: A | K27: B | L27: B | M27: A | N27: A | O27: A | P27: B | Q27: A | R27: E | S27: E | T27: E | U27: A | V27: B | W27: B | X27: B | Y27: B | AA27: =IFERROR(VALUE(TRIM(LEFT($E27,SEARCH("x",$E27)-1))),"") -> 1 | AB27: =IFERROR(VALUE(TRIM(MID($E27,SEARCH("x",$E27)+1,10))),"") -> 0 | AC27: =IF(OR($AA27="",$AB27=""),"",IF($AA27>$AB27,"A",IF($AA27<$AB27,"B","E"))) -> A
B28: Suíça x Bósnia e Herzeg. | C28: =TRIM(LEFT(B28,FIND(" x ",B28)-1)) -> Suíça | D28: =TRIM(MID(B28,FIND(" x ",B28)+3,100)) -> Bósnia e Herzeg. | E28: 4x1 | G28: A | H28: A | I28: E | J28: A | K28: A | L28: A | M28: A | N28: A | O28: A | P28: A | Q28: A | R28: E | S28: A | T28: E | U28: A | V28: A | W28: A | X28: A | Y28: A | AA28: =IFERROR(VALUE(TRIM(LEFT($E28,SEARCH("x",$E28)-1))),"") -> 4 | AB28: =IFERROR(VALUE(TRIM(MID($E28,SEARCH("x",$E28)+1,10))),"") -> 1 | AC28: =IF(OR($AA28="",$AB28=""),"",IF($AA28>$AB28,"A",IF($AA28<$AB28,"B","E"))) -> A
B29: Canadá x Catar | C29: =TRIM(LEFT(B29,FIND(" x ",B29)-1)) -> Canadá | D29: =TRIM(MID(B29,FIND(" x ",B29)+3,100)) -> Catar | E29: 6x0 | G29: A | H29: A | I29: A | J29: A | K29: A | L29: A | M29: A | N29: A | O29: A | P29: A | Q29: A | R29: A | S29: E | T29: A | U29: A | V29: A | W29: B | X29: B | Y29: A | AA29: =IFERROR(VALUE(TRIM(LEFT($E29,SEARCH("x",$E29)-1))),"") -> 6 | AB29: =IFERROR(VALUE(TRIM(MID($E29,SEARCH("x",$E29)+1,10))),"") -> 0 | AC29: =IF(OR($AA29="",$AB29=""),"",IF($AA29>$AB29,"A",IF($AA29<$AB29,"B","E"))) -> A
A30: 46192 | B30: Escócia x Marrocos | C30: =TRIM(LEFT(B30,FIND(" x ",B30)-1)) -> Escócia | D30: =TRIM(MID(B30,FIND(" x ",B30)+3,100)) -> Marrocos | E30: 0x1 | G30: B | H30: B | I30: B | J30: B | K30: B | L30: B | M30: B | N30: B | O30: B | P30: B | Q30: B | R30: B | T30: E | U30: B | V30: B | W30: B | X30: B | Y30: B | Z30: B | AA30: =IFERROR(VALUE(TRIM(LEFT($E30,SEARCH("x",$E30)-1))),"") -> 0 | AB30: =IFERROR(VALUE(TRIM(MID($E30,SEARCH("x",$E30)+1,10))),"") -> 1 | AC30: =IF(OR($AA30="",$AB30=""),"",IF($AA30>$AB30,"A",IF($AA30<$AB30,"B","E"))) -> B
B31: Brasil x Haiti | C31: =TRIM(LEFT(B31,FIND(" x ",B31)-1)) -> Brasil | D31: =TRIM(MID(B31,FIND(" x ",B31)+3,100)) -> Haiti | E31: 3x0 | G31: A | H31: A | I31: A | J31: A | K31: A | L31: A | M31: A | N31: A | O31: A | P31: A | Q31: A | R31: A | S31: A | T31: A | U31: A | V31: A | W31: A | X31: A | Y31: A | Z31: A | AA31: =IFERROR(VALUE(TRIM(LEFT($E31,SEARCH("x",$E31)-1))),"") -> 3 | AB31: =IFERROR(VALUE(TRIM(MID($E31,SEARCH("x",$E31)+1,10))),"") -> 0 | AC31: =IF(OR($AA31="",$AB31=""),"",IF($AA31>$AB31,"A",IF($AA31<$AB31,"B","E"))) -> A
B32: Estados Unidos x Austrália | C32: =TRIM(LEFT(B32,FIND(" x ",B32)-1)) -> Estados Unidos | D32: =TRIM(MID(B32,FIND(" x ",B32)+3,100)) -> Austrália | E32: 2x0 | G32: A | H32: A | I32: A | J32: A | K32: E | L32: A | M32: A | N32: A | O32: A | P32: A | Q32: A | R32: A | T32: E | U32: A | V32: A | W32: A | X32: A | Y32: A | Z32: A | AA32: =IFERROR(VALUE(TRIM(LEFT($E32,SEARCH("x",$E32)-1))),"") -> 2 | AB32: =IFERROR(VALUE(TRIM(MID($E32,SEARCH("x",$E32)+1,10))),"") -> 0 | AC32: =IF(OR($AA32="",$AB32=""),"",IF($AA32>$AB32,"A",IF($AA32<$AB32,"B","E"))) -> A
B33: Turquia x Paraguai | C33: =TRIM(LEFT(B33,FIND(" x ",B33)-1)) -> Turquia | D33: =TRIM(MID(B33,FIND(" x ",B33)+3,100)) -> Paraguai | E33: 0x1 | G33: A | H33: B | I33: A | J33: A | K33: A | L33: E | M33: A | N33: A | O33: E | P33: A | Q33: E | R33: A | S33: E | T33: A | U33: A | V33: A | W33: B | X33: B | Y33: A | Z33: B | AA33: =IFERROR(VALUE(TRIM(LEFT($E33,SEARCH("x",$E33)-1))),"") -> 0 | AB33: =IFERROR(VALUE(TRIM(MID($E33,SEARCH("x",$E33)+1,10))),"") -> 1 | AC33: =IF(OR($AA33="",$AB33=""),"",IF($AA33>$AB33,"A",IF($AA33<$AB33,"B","E"))) -> B
A34: 46193 | B34: Alemanha x Costa do Marfim | C34: =TRIM(LEFT(B34,FIND(" x ",B34)-1)) -> Alemanha | D34: =TRIM(MID(B34,FIND(" x ",B34)+3,100)) -> Costa do Marfim | E34: 2x1 | G34: A | H34: A | I34: A | J34: A | K34: A | L34: A | M34: A | N34: A | O34: A | P34: A | Q34: A | R34: A | S34: A | T34: A | U34: A | V34: E | W34: A | X34: A | Y34: A | Z34: E | AA34: =IFERROR(VALUE(TRIM(LEFT($E34,SEARCH("x",$E34)-1))),"") -> 2 | AB34: =IFERROR(VALUE(TRIM(MID($E34,SEARCH("x",$E34)+1,10))),"") -> 1 | AC34: =IF(OR($AA34="",$AB34=""),"",IF($AA34>$AB34,"A",IF($AA34<$AB34,"B","E"))) -> A
B35: Equador x Curaçao | C35: =TRIM(LEFT(B35,FIND(" x ",B35)-1)) -> Equador | D35: =TRIM(MID(B35,FIND(" x ",B35)+3,100)) -> Curaçao | E35: 0x0 | G35: A | H35: A | I35: A | J35: A | K35: A | L35: A | M35: A | N35: A | O35: A | P35: A | Q35: A | R35: A | S35: A | T35: A | U35: A | V35: A | W35: A | X35: A | Y35: A | Z35: E | AA35: =IFERROR(VALUE(TRIM(LEFT($E35,SEARCH("x",$E35)-1))),"") -> 0 | AB35: =IFERROR(VALUE(TRIM(MID($E35,SEARCH("x",$E35)+1,10))),"") -> 0 | AC35: =IF(OR($AA35="",$AB35=""),"",IF($AA35>$AB35,"A",IF($AA35<$AB35,"B","E"))) -> E
B36: Países Baixos x Suécia | C36: =TRIM(LEFT(B36,FIND(" x ",B36)-1)) -> Países Baixos | D36: =TRIM(MID(B36,FIND(" x ",B36)+3,100)) -> Suécia | E36: 5x1 | G36: A | H36: E | I36: B | J36: B | K36: A | L36: A | M36: A | N36: A | O36: A | P36: E | Q36: A | R36: A | S36: A | T36: A | U36: E | V36: A | W36: A | X36: A | Y36: A | Z36: E | AA36: =IFERROR(VALUE(TRIM(LEFT($E36,SEARCH("x",$E36)-1))),"") -> 5 | AB36: =IFERROR(VALUE(TRIM(MID($E36,SEARCH("x",$E36)+1,10))),"") -> 1 | AC36: =IF(OR($AA36="",$AB36=""),"",IF($AA36>$AB36,"A",IF($AA36<$AB36,"B","E"))) -> A
B37: Tunísia x Japão | C37: =TRIM(LEFT(B37,FIND(" x ",B37)-1)) -> Tunísia | D37: =TRIM(MID(B37,FIND(" x ",B37)+3,100)) -> Japão | E37: 0x4 | G37: B | H37: B | I37: B | J37: B | K37: B | L37: B | M37: B | N37: B | O37: B | P37: B | Q37: E | R37: B | S37: B | T37: B | U37: B | V37: B | W37: B | X37: B | Y37: B | Z37: B | AA37: =IFERROR(VALUE(TRIM(LEFT($E37,SEARCH("x",$E37)-1))),"") -> 0 | AB37: =IFERROR(VALUE(TRIM(MID($E37,SEARCH("x",$E37)+1,10))),"") -> 4 | AC37: =IF(OR($AA37="",$AB37=""),"",IF($AA37>$AB37,"A",IF($AA37<$AB37,"B","E"))) -> B
A38: 46194 | B38: Bélgica x Irã | C38: =TRIM(LEFT(B38,FIND(" x ",B38)-1)) -> Bélgica | D38: =TRIM(MID(B38,FIND(" x ",B38)+3,100)) -> Irã | E38: 0x0 | G38: A | H38: A | I38: A | J38: A | K38: A | L38: A | M38: A | N38: A | O38: A | P38: A | Q38: A | S38: E | T38: A | U38: A | V38: E | W38: E | X38: A | Y38: A | Z38: E | AA38: =IFERROR(VALUE(TRIM(LEFT($E38,SEARCH("x",$E38)-1))),"") -> 0 | AB38: =IFERROR(VALUE(TRIM(MID($E38,SEARCH("x",$E38)+1,10))),"") -> 0 | AC38: =IF(OR($AA38="",$AB38=""),"",IF($AA38>$AB38,"A",IF($AA38<$AB38,"B","E"))) -> E
B39: Nova Zelândia x Egito | C39: =TRIM(LEFT(B39,FIND(" x ",B39)-1)) -> Nova Zelândia | D39: =TRIM(MID(B39,FIND(" x ",B39)+3,100)) -> Egito | E39: 1x3 | G39: E | H39: A | I39: B | J39: E | K39: E | L39: E | M39: B | N39: B | O39: B | P39: B | Q39: A | R39: A | S39: E | T39: B | U39: B | V39: B | W39: E | X39: B | Y39: A | Z39: B | AA39: =IFERROR(VALUE(TRIM(LEFT($E39,SEARCH("x",$E39)-1))),"") -> 1 | AB39: =IFERROR(VALUE(TRIM(MID($E39,SEARCH("x",$E39)+1,10))),"") -> 3 | AC39: =IF(OR($AA39="",$AB39=""),"",IF($AA39>$AB39,"A",IF($AA39<$AB39,"B","E"))) -> B
B40: Espanha x Arábia Saudita | C40: =TRIM(LEFT(B40,FIND(" x ",B40)-1)) -> Espanha | D40: =TRIM(MID(B40,FIND(" x ",B40)+3,100)) -> Arábia Saudita | E40: 4x0 | G40: A | H40: A | I40: A | J40: A | K40: A | L40: A | M40: A | N40: A | O40: A | P40: A | Q40: A | S40: A | T40: A | U40: A | V40: A | W40: A | X40: A | Y40: A | Z40: A | AA40: =IFERROR(VALUE(TRIM(LEFT($E40,SEARCH("x",$E40)-1))),"") -> 4 | AB40: =IFERROR(VALUE(TRIM(MID($E40,SEARCH("x",$E40)+1,10))),"") -> 0 | AC40: =IF(OR($AA40="",$AB40=""),"",IF($AA40>$AB40,"A",IF($AA40<$AB40,"B","E"))) -> A
...

Sheet MATA-MATA 32
A1: DATAS | B1: CONFRONTOS | C1: TIME A | D1: TIME B | E1: PLACAR | F1: Penalti | G1: Prorrogação | I1: Alex | J1: Bonfim | K1: Christian | L1: Cleiton | M1: Daniel | N1: David | O1: Douglas | P1: Dunga | Q1: Felipe | R1: Gabriel | S1: Giliarde | T1: Gustavo | U1: Gustavo Lima | V1: Heitor | W1: Juninho | X1: Leonardo | Y1: Patrick | Z1: Rasta | AA1: Renan | AB1: Sanches | AC1: Gols A | AD1: Gols B | AE1: RESULTADO
A2: 46201 | B2: África do Sul x Canadá | C2: =TRIM(LEFT(B2,FIND(" x ",B2)-1)) -> África do Sul | D2: =TRIM(MID(B2,FIND(" x ",B2)+3,100)) -> Canadá | E2: 0x1 | I2: B | J2: A | K2: B | L2: A | M2: E | N2: B | O2: B | P2: B | Q2: B | R2: B | S2: A | U2: B | V2: B | W2: B | X2: B | Z2: A | AA2: B | AC2: =IFERROR(VALUE(TRIM(LEFT($E2,SEARCH("x",$E2)-1))),"") -> 0 | AD2: =IFERROR(VALUE(TRIM(MID($E2,SEARCH("x",$E2)+1,10))),"") -> 1 | AE2: =IF(OR($AC2="",$AD2=""),"",IF($AC2>$AD2,"A",IF($AC2<$AD2,"B","E"))) -> B
A3: 46202 | B3: Alemanha x Paraguai | C3: =TRIM(LEFT(B3,FIND(" x ",B3)-1)) -> Alemanha | D3: =TRIM(MID(B3,FIND(" x ",B3)+3,100)) -> Paraguai | E3: 1x1 | F3: B | I3: A | J3: A | K3: A | L3: A | M3: A | N3: A | O3: A | P3: A | Q3: A | R3: A | S3: A | T3: A | U3: A | V3: A | W3: A | X3: A | Y3: A | Z3: B | AA3: A | AB3: A | AC3: =IFERROR(VALUE(TRIM(LEFT($E3,SEARCH("x",$E3)-1))),"") -> 1 | AD3: =IFERROR(VALUE(TRIM(MID($E3,SEARCH("x",$E3)+1,10))),"") -> 1 | AE3: =IF(OR($AC3="",$AD3=""),"",IF($AC3>$AD3,"A",IF($AC3<$AD3,"B","E"))) -> E
B4: Países Baixos x Marrocos | C4: =TRIM(LEFT(B4,FIND(" x ",B4)-1)) -> Países Baixos | D4: =TRIM(MID(B4,FIND(" x ",B4)+3,100)) -> Marrocos | E4: 1x1 | F4: B | I4: A | J4: B | K4: A | L4: A | M4: A | N4: A | O4: A | P4: A | Q4: E | R4: B | S4: B | T4: B | U4: A | V4: E | W4: A | X4: A | Y4: A | Z4: A | AA4: A | AB4: A | AC4: =IFERROR(VALUE(TRIM(LEFT($E4,SEARCH("x",$E4)-1))),"") -> 1 | AD4: =IFERROR(VALUE(TRIM(MID($E4,SEARCH("x",$E4)+1,10))),"") -> 1 | AE4: =IF(OR($AC4="",$AD4=""),"",IF($AC4>$AD4,"A",IF($AC4<$AD4,"B","E"))) -> E
B5: Brasil x Japão | C5: =TRIM(LEFT(B5,FIND(" x ",B5)-1)) -> Brasil | D5: =TRIM(MID(B5,FIND(" x ",B5)+3,100)) -> Japão | E5: 2x1 | I5: A | J5: A | K5: A | L5: A | M5: A | N5: A | O5: A | P5: A | Q5: A | R5: A | S5: A | T5: A | U5: A | V5: A | W5: A | X5: A | Y5: A | Z5: A | AA5: A | AB5: A | AC5: =IFERROR(VALUE(TRIM(LEFT($E5,SEARCH("x",$E5)-1))),"") -> 2 | AD5: =IFERROR(VALUE(TRIM(MID($E5,SEARCH("x",$E5)+1,10))),"") -> 1 | AE5: =IF(OR($AC5="",$AD5=""),"",IF($AC5>$AD5,"A",IF($AC5<$AD5,"B","E"))) -> A
A6: 46203 | B6: França x Suécia | C6: =TRIM(LEFT(B6,FIND(" x ",B6)-1)) -> França | D6: =TRIM(MID(B6,FIND(" x ",B6)+3,100)) -> Suécia | E6: 3X0 | I6: A | J6: A | K6: A | L6: A | M6: A | N6: A | O6: A | P6: A | Q6: A | R6: A | S6: A | T6: A | U6: A | V6: A | W6: A | X6: A | Y6: A | Z6: A | AA6: A | AB6: A | AC6: =IFERROR(VALUE(TRIM(LEFT($E6,SEARCH("x",$E6)-1))),"") -> 3 | AD6: =IFERROR(VALUE(TRIM(MID($E6,SEARCH("x",$E6)+1,10))),"") -> 0 | AE6: =IF(OR($AC6="",$AD6=""),"",IF($AC6>$AD6,"A",IF($AC6<$AD6,"B","E"))) -> A
B7: Costa do Marfim x Noruega | C7: =TRIM(LEFT(B7,FIND(" x ",B7)-1)) -> Costa do Marfim | D7: =TRIM(MID(B7,FIND(" x ",B7)+3,100)) -> Noruega | E7: 1x2 | I7: B | J7: A | K7: B | L7: B | M7: B | N7: B | O7: B | P7: B | Q7: A | R7: B | S7: B | T7: E | U7: B | V7: E | W7: E | X7: A | Y7: E | Z7: A | AA7: B | AB7: B | AC7: =IFERROR(VALUE(TRIM(LEFT($E7,SEARCH("x",$E7)-1))),"") -> 1 | AD7: =IFERROR(VALUE(TRIM(MID($E7,SEARCH("x",$E7)+1,10))),"") -> 2 | AE7: =IF(OR($AC7="",$AD7=""),"",IF($AC7>$AD7,"A",IF($AC7<$AD7,"B","E"))) -> B
B8: México x Equador | C8: =TRIM(LEFT(B8,FIND(" x ",B8)-1)) -> México | D8: =TRIM(MID(B8,FIND(" x ",B8)+3,100)) -> Equador | E8: 2x0 | I8: A | J8: A | K8: A | L8: A | M8: A | N8: A | O8: A | P8: A | Q8: B | R8: B | S8: A | T8: E | U8: B | V8: A | W8: A | X8: A | Y8: B | Z8: A | AA8: A | AB8: A | AC8: =IFERROR(VALUE(TRIM(LEFT($E8,SEARCH("x",$E8)-1))),"") -> 2 | AD8: =IFERROR(VALUE(TRIM(MID($E8,SEARCH("x",$E8)+1,10))),"") -> 0 | AE8: =IF(OR($AC8="",$AD8=""),"",IF($AC8>$AD8,"A",IF($AC8<$AD8,"B","E"))) -> A
A9: 46204 | B9: Inglaterra x Rep. Dem. Congo | C9: =TRIM(LEFT(B9,FIND(" x ",B9)-1)) -> Inglaterra | D9: =TRIM(MID(B9,FIND(" x ",B9)+3,100)) -> Rep. Dem. Congo | E9: 2x1 | I9: A | J9: A | K9: A | L9: A | M9: A | N9: A | O9: A | P9: A | Q9: A | R9: A | S9: A | T9: A | U9: A | V9: A | W9: A | X9: A | Y9: A | Z9: A | AA9: A | AC9: =IFERROR(VALUE(TRIM(LEFT($E9,SEARCH("x",$E9)-1))),"") -> 2 | AD9: =IFERROR(VALUE(TRIM(MID($E9,SEARCH("x",$E9)+1,10))),"") -> 1 | AE9: =IF(OR($AC9="",$AD9=""),"",IF($AC9>$AD9,"A",IF($AC9<$AD9,"B","E"))) -> A
B10: Estados Unidos x Bósnia e Herzeg. | C10: =TRIM(LEFT(B10,FIND(" x ",B10)-1)) -> Estados Unidos | D10: =TRIM(MID(B10,FIND(" x ",B10)+3,100)) -> Bósnia e Herzeg. | E10: 2x0 | I10: A | J10: A | K10: A | L10: A | M10: A | N10: A | O10: A | P10: A | Q10: A | R10: A | S10: A | T10: A | U10: A | V10: A | W10: A | X10: A | Y10: A | Z10: A | AA10: A | AB10: A | AC10: =IFERROR(VALUE(TRIM(LEFT($E10,SEARCH("x",$E10)-1))),"") -> 2 | AD10: =IFERROR(VALUE(TRIM(MID($E10,SEARCH("x",$E10)+1,10))),"") -> 0 | AE10: =IF(OR($AC10="",$AD10=""),"",IF($AC10>$AD10,"A",IF($AC10<$AD10,"B","E"))) -> A
B11: Bélgica x Senegal | C11: =TRIM(LEFT(B11,FIND(" x ",B11)-1)) -> Bélgica | D11: =TRIM(MID(B11,FIND(" x ",B11)+3,100)) -> Senegal | E11: 2x2 | G11: A | I11: A | J11: B | K11: B | L11: A | M11: A | N11: B | O11: B | P11: A | Q11: E | R11: B | S11: A | T11: B | U11: B | V11: E | W11: A | X11: B | Y11: B | Z11: A | AA11: B | AB11: E | AC11: =IFERROR(VALUE(TRIM(LEFT($E11,SEARCH("x",$E11)-1))),"") -> 2 | AD11: =IFERROR(VALUE(TRIM(MID($E11,SEARCH("x",$E11)+1,10))),"") -> 2 | AE11: =IF(OR($AC11="",$AD11=""),"",IF($AC11>$AD11,"A",IF($AC11<$AD11,"B","E"))) -> E
A12: 46205 | B12: Portugal x Croácia | C12: =TRIM(LEFT(B12,FIND(" x ",B12)-1)) -> Portugal | D12: =TRIM(MID(B12,FIND(" x ",B12)+3,100)) -> Croácia | E12: 2x1 | I12: A | J12: A | K12: E | L12: A | M12: E | N12: A | O12: A | P12: A | Q12: B | R12: A | S12: E | T12: E | U12: A | V12: B | W12: A | X12: A | Y12: B | Z12: A | AA12: E | AB12: B | AC12: =IFERROR(VALUE(TRIM(LEFT($E12,SEARCH("x",$E12)-1))),"") -> 2 | AD12: =IFERROR(VALUE(TRIM(MID($E12,SEARCH("x",$E12)+1,10))),"") -> 1 | AE12: =IF(OR($AC12="",$AD12=""),"",IF($AC12>$AD12,"A",IF($AC12<$AD12,"B","E"))) -> A
B13: Espanha x Áustria | C13: =TRIM(LEFT(B13,FIND(" x ",B13)-1)) -> Espanha | D13: =TRIM(MID(B13,FIND(" x ",B13)+3,100)) -> Áustria | E13: 3x0 | I13: A | J13: A | K13: A | L13: A | M13: A | N13: A | O13: A | P13: A | Q13: A | R13: A | S13: A | T13: A | U13: A | V13: A | W13: A | X13: A | Y13: A | Z13: A | AA13: A | AB13: A | AC13: =IFERROR(VALUE(TRIM(LEFT($E13,SEARCH("x",$E13)-1))),"") -> 3 | AD13: =IFERROR(VALUE(TRIM(MID($E13,SEARCH("x",$E13)+1,10))),"") -> 0 | AE13: =IF(OR($AC13="",$AD13=""),"",IF($AC13>$AD13,"A",IF($AC13<$AD13,"B","E"))) -> A
B14: Suíça x Argélia | C14: =TRIM(LEFT(B14,FIND(" x ",B14)-1)) -> Suíça | D14: =TRIM(MID(B14,FIND(" x ",B14)+3,100)) -> Argélia | E14: 2x0 | I14: A | J14: A | K14: A | L14: E | M14: A | N14: E | O14: A | P14: A | Q14: A | R14: E | S14: E | T14: E | U14: A | V14: A | W14: A | X14: A | Y14: E | Z14: A | AA14: A | AB14: B | AC14: =IFERROR(VALUE(TRIM(LEFT($E14,SEARCH("x",$E14)-1))),"") -> 2 | AD14: =IFERROR(VALUE(TRIM(MID($E14,SEARCH("x",$E14)+1,10))),"") -> 0 | AE14: =IF(OR($AC14="",$AD14=""),"",IF($AC14>$AD14,"A",IF($AC14<$AD14,"B","E"))) -> A
A15: 46206 | B15: Colômbia x Gana | C15: =TRIM(LEFT(B15,FIND(" x ",B15)-1)) -> Colômbia | D15: =TRIM(MID(B15,FIND(" x ",B15)+3,100)) -> Gana | E15: #x# | I15: A | J15: A | K15: A | L15: A | M15: A | N15: E | O15: A | P15: A | Q15: A | R15: A | S15: A | T15: E | U15: A | V15: E | W15: A | X15: A | Y15: E | Z15: A | AA15: A | AB15: B | AC15: =IFERROR(VALUE(TRIM(LEFT($E15,SEARCH("x",$E15)-1))),"") | AD15: =IFERROR(VALUE(TRIM(MID($E15,SEARCH("x",$E15)+1,10))),"") | AE15: =IF(OR($AC15="",$AD15=""),"",IF($AC15>$AD15,"A",IF($AC15<$AD15,"B","E")))
B16: Argentina x Cabo Verde | C16: =TRIM(LEFT(B16,FIND(" x ",B16)-1)) -> Argentina | D16: =TRIM(MID(B16,FIND(" x ",B16)+3,100)) -> Cabo Verde | E16: 1x1 | I16: A | J16: A | K16: A | L16: A | M16: A | N16: A | O16: A | P16: A | Q16: A | R16: A | S16: A | T16: A | U16: A | V16: A | W16: A | X16: A | Y16: A | Z16: A | AA16: B | AB16: B | AC16: =IFERROR(VALUE(TRIM(LEFT($E16,SEARCH("x",$E16)-1))),"") -> 1 | AD16: =IFERROR(VALUE(TRIM(MID($E16,SEARCH("x",$E16)+1,10))),"") -> 1 | AE16: =IF(OR($AC16="",$AD16=""),"",IF($AC16>$AD16,"A",IF($AC16<$AD16,"B","E"))) -> E
B17: Austrália x Egito | C17: =TRIM(LEFT(B17,FIND(" x ",B17)-1)) -> Austrália | D17: =TRIM(MID(B17,FIND(" x ",B17)+3,100)) -> Egito | E17: 1x1 | I17: B | J17: E | K17: B | L17: E | M17: B | O17: B | P17: B | Q17: B | R17: B | S17: E | T17: B | U17: B | V17: E | W17: B | X17: B | Y17: B | Z17: B | AA17: B | AB17: E | AC17: =IFERROR(VALUE(TRIM(LEFT($E17,SEARCH("x",$E17)-1))),"") -> 1 | AD17: =IFERROR(VALUE(TRIM(MID($E17,SEARCH("x",$E17)+1,10))),"") -> 1 | AE17: =IF(OR($AC17="",$AD17=""),"",IF($AC17>$AD17,"A",IF($AC17<$AD17,"B","E"))) -> E
H18: TOTAL | I18: {=SUMPRODUCT(--(UPPER(I2:I17)=$AE$2:$AE$17),--($AE$2:$AE$17<>""))+ORGANIZAÇÃO!G74} -> 52 | J18: {=SUMPRODUCT(--(UPPER(J2:J17)=$AE$2:$AE$17),--($AE$2:$AE$17<>""))+ORGANIZAÇÃO!H74} -> 51 | K18: {=SUMPRODUCT(--(UPPER(K2:K17)=$AE$2:$AE$17),--($AE$2:$AE$17<>""))+ORGANIZAÇÃO!I74} -> 51 | L18: {=SUMPRODUCT(--(UPPER(L2:L17)=$AE$2:$AE$17),--($AE$2:$AE$17<>""))+ORGANIZAÇÃO!J74} -> 53 | M18: {=SUMPRODUCT(--(UPPER(M2:M17)=$AE$2:$AE$17),--($AE$2:$AE$17<>""))+ORGANIZAÇÃO!K74} -> 48 | N18: {=SUMPRODUCT(--(UPPER(N2:N17)=$AE$2:$AE$17),--($AE$2:$AE$17<>""))+ORGANIZAÇÃO!L74} -> 49 | O18: {=SUMPRODUCT(--(UPPER(O2:O17)=$AE$2:$AE$17),--($AE$2:$AE$17<>""))+ORGANIZAÇÃO!M74} -> 54 | P18: {=SUMPRODUCT(--(UPPER(P2:P17)=$AE$2:$AE$17),--($AE$2:$AE$17<>""))+ORGANIZAÇÃO!N74} -> 57 | ... AB18: {=SUMPRODUCT(--(UPPER(AB2:AB17)=$AE$2:$AE$17),--($AE$2:$AE$17<>""))+ORGANIZAÇÃO!Z74} -> 41

Sheet MATA-MATA 16
A1: DATAS | B1: CONFRONTOS | C1: TIME A | D1: TIME B | E1: PLACAR | F1: Penalti | G1: Prorrogação | I1: Alex | J1: Bonfim | K1: Christian | L1: Cleiton | M1: Daniel | N1: David | O1: Douglas | P1: Dunga | Q1: Felipe | R1: Gabriel | S1: Giliarde | T1: Gustavo | U1: Gustavo Lima | V1: Heitor | W1: Juninho | X1: Leonardo | Y1: Patrick | Z1: Rasta | AA1: Renan | AB1: Sanches | AC1: Gols A | AD1: Gols B | AE1: RESULTADO
A2: 46207 | B2: Paraguai x França | C2: =TRIM(LEFT(B2,FIND(" x ",B2)-1)) -> Paraguai | D2: =TRIM(MID(B2,FIND(" x ",B2)+3,100)) -> França | E2: #x# | AC2: =IFERROR(VALUE(TRIM(LEFT($E2,SEARCH("x",$E2)-1))),"") | AD2: =IFERROR(VALUE(TRIM(MID($E2,SEARCH("x",$E2)+1,10))),"") | AE2: =IF(OR($AC2="",$AD2=""),"",IF($AC2>$AD2,"A",IF($AC2<$AD2,"B","E")))
B3: Canadá x Marrocos | C3: =TRIM(LEFT(B3,FIND(" x ",B3)-1)) -> Canadá | D3: =TRIM(MID(B3,FIND(" x ",B3)+3,100)) -> Marrocos | E3: #x# | AC3: =IFERROR(VALUE(TRIM(LEFT($E3,SEARCH("x",$E3)-1))),"") | AD3: =IFERROR(VALUE(TRIM(MID($E3,SEARCH("x",$E3)+1,10))),"") | AE3: =IF(OR($AC3="",$AD3=""),"",IF($AC3>$AD3,"A",IF($AC3<$AD3,"B","E")))
A4: 46208 | B4: Brasil x Noruega | C4: =TRIM(LEFT(B4,FIND(" x ",B4)-1)) -> Brasil | D4: =TRIM(MID(B4,FIND(" x ",B4)+3,100)) -> Noruega | E4: #x# | AC4: =IFERROR(VALUE(TRIM(LEFT($E4,SEARCH("x",$E4)-1))),"") | AD4: =IFERROR(VALUE(TRIM(MID($E4,SEARCH("x",$E4)+1,10))),"") | AE4: =IF(OR($AC4="",$AD4=""),"",IF($AC4>$AD4,"A",IF($AC4<$AD4,"B","E")))
B5: México x Inglaterra | C5: =TRIM(LEFT(B5,FIND(" x ",B5)-1)) -> México | D5: =TRIM(MID(B5,FIND(" x ",B5)+3,100)) -> Inglaterra | E5: #x# | AC5: =IFERROR(VALUE(TRIM(LEFT($E5,SEARCH("x",$E5)-1))),"") | AD5: =IFERROR(VALUE(TRIM(MID($E5,SEARCH("x",$E5)+1,10))),"") | AE5: =IF(OR($AC5="",$AD5=""),"",IF($AC5>$AD5,"A",IF($AC5<$AD5,"B","E")))
A6: 46209 | B6: Portugal x Espanha | C6: =TRIM(LEFT(B6,FIND(" x ",B6)-1)) -> Portugal | D6: =TRIM(MID(B6,FIND(" x ",B6)+3,100)) -> Espanha | E6: #x# | AC6: =IFERROR(VALUE(TRIM(LEFT($E6,SEARCH("x",$E6)-1))),"") | AD6: =IFERROR(VALUE(TRIM(MID($E6,SEARCH("x",$E6)+1,10))),"") | AE6: =IF(OR($AC6="",$AD6=""),"",IF($AC6>$AD6,"A",IF($AC6<$AD6,"B","E")))
B7: Estados Unidos x Bélgica | C7: =TRIM(LEFT(B7,FIND(" x ",B7)-1)) -> Estados Unidos | D7: =TRIM(MID(B7,FIND(" x ",B7)+3,100)) -> Bélgica | E7: #x# | AC7: =IFERROR(VALUE(TRIM(LEFT($E7,SEARCH("x",$E7)-1))),"") | AD7: =IFERROR(VALUE(TRIM(MID($E7,SEARCH("x",$E7)+1,10))),"") | AE7: =IF(OR($AC7="",$AD7=""),"",IF($AC7>$AD7,"A",IF($AC7<$AD7,"B","E")))
A8: 46210 | B8: Vencedor Jogo 15 x Egito | C8: =TRIM(LEFT(B8,FIND(" x ",B8)-1)) -> Vencedor Jogo 15 | D8: =TRIM(MID(B8,FIND(" x ",B8)+3,100)) -> Egito | E8: #x# | AC8: =IFERROR(VALUE(TRIM(LEFT($E8,SEARCH("x",$E8)-1))),"") | AD8: =IFERROR(VALUE(TRIM(MID($E8,SEARCH("x",$E8)+1,10))),"") | AE8: =IF(OR($AC8="",$AD8=""),"",IF($AC8>$AD8,"A",IF($AC8<$AD8,"B","E")))
B9: Suíça x Vencedor Jogo 14 | C9: =TRIM(LEFT(B9,FIND(" x ",B9)-1)) -> Suíça | D9: =TRIM(MID(B9,FIND(" x ",B9)+3,100)) -> Vencedor Jogo 14 | E9: #x# | AC9: =IFERROR(VALUE(TRIM(LEFT($E9,SEARCH("x",$E9)-1))),"") | AD9: =IFERROR(VALUE(TRIM(MID($E9,SEARCH("x",$E9)+1,10))),"") | AE9: =IF(OR($AC9="",$AD9=""),"",IF($AC9>$AD9,"A",IF($AC9<$AD9,"B","E")))
H10: TOTAL | I10: {=SUMPRODUCT(--(UPPER(I2:I9)=$AE$2:$AE$9),--($AE$2:$AE$9<>""))+'MATA-MATA 32'!I18} -> 52 | J10: {=SUMPRODUCT(--(UPPER(J2:J9)=$AE$2:$AE$9),--($AE$2:$AE$9<>""))+'MATA-MATA 32'!J18} -> 51 | K10: {=SUMPRODUCT(--(UPPER(K2:K9)=$AE$2:$AE$9),--($AE$2:$AE$9<>""))+'MATA-MATA 32'!K18} -> 51 | L10: {=SUMPRODUCT(--(UPPER(L2:L9)=$AE$2:$AE$9),--($AE$2:$AE$9<>""))+'MATA-MATA 32'!L18} -> 53 | M10: {=SUMPRODUCT(--(UPPER(M2:M9)=$AE$2:$AE$9),--($AE$2:$AE$9<>""))+'MATA-MATA 32'!M18} -> 48 | N10: {=SUMPRODUCT(--(UPPER(N2:N9)=$AE$2:$AE$9),--($AE$2:$AE$9<>""))+'MATA-MATA 32'!N18} -> 49 | O10: {=SUMPRODUCT(--(UPPER(O2:O9)=$AE$2:$AE$9),--($AE$2:$AE$9<>""))+'MATA-MATA 32'!O18} -> 54 | P10: {=SUMPRODUCT(--(UPPER(P2:P9)=$AE$2:$AE$9),--($AE$2:$AE$9<>""))+'MATA-MATA 32'!P18} -> 57 | ... AB10: {=SUMPRODUCT(--(UPPER(AB2:AB9)=$AE$2:$AE$9),--($AE$2:$AE$9<>""))+'MATA-MATA 32'!AB18} -> 41

Sheet MATA-MATA 8
A1: DATAS | B1: CONFRONTOS | C1: TIME A | D1: TIME B | E1: PLACAR | F1: Penalti | G1: Prorrogação | I1: Alex | J1: Bonfim | K1: Christian | L1: Cleiton | M1: Daniel | N1: David | O1: Douglas | P1: Dunga | Q1: Felipe | R1: Gabriel | S1: Giliarde | T1: Gustavo | U1: Gustavo Lima | V1: Heitor | W1: Juninho | X1: Leonardo | Y1: Patrick | Z1: Rasta | AA1: Renan | AB1: Sanches | AC1: Gols A | AD1: Gols B | AE1: RESULTADO
B2: Vencedor Oitava 1 x Vencedor Oitava 2 | C2: =TRIM(LEFT(B2,FIND(" x ",B2)-1)) -> Vencedor Oitava 1 | D2: =TRIM(MID(B2,FIND(" x ",B2)+3,100)) -> Vencedor Oitava 2 | E2: #x# | AC2: =IFERROR(VALUE(TRIM(LEFT($E2,SEARCH("x",$E2)-1))),"") | AD2: =IFERROR(VALUE(TRIM(MID($E2,SEARCH("x",$E2)+1,10))),"") | AE2: =IF(OR($AC2="",$AD2=""),"",IF($AC2>$AD2,"A",IF($AC2<$AD2,"B","E")))
B3: Vencedor Oitava 3 x Vencedor Oitava 4 | C3: =TRIM(LEFT(B3,FIND(" x ",B3)-1)) -> Vencedor Oitava 3 | D3: =TRIM(MID(B3,FIND(" x ",B3)+3,100)) -> Vencedor Oitava 4 | E3: #x# | AC3: =IFERROR(VALUE(TRIM(LEFT($E3,SEARCH("x",$E3)-1))),"") | AD3: =IFERROR(VALUE(TRIM(MID($E3,SEARCH("x",$E3)+1,10))),"") | AE3: =IF(OR($AC3="",$AD3=""),"",IF($AC3>$AD3,"A",IF($AC3<$AD3,"B","E")))
B4: Vencedor Oitava 5 x Vencedor Oitava 6 | C4: =TRIM(LEFT(B4,FIND(" x ",B4)-1)) -> Vencedor Oitava 5 | D4: =TRIM(MID(B4,FIND(" x ",B4)+3,100)) -> Vencedor Oitava 6 | E4: #x# | AC4: =IFERROR(VALUE(TRIM(LEFT($E4,SEARCH("x",$E4)-1))),"") | AD4: =IFERROR(VALUE(TRIM(MID($E4,SEARCH("x",$E4)+1,10))),"") | AE4: =IF(OR($AC4="",$AD4=""),"",IF($AC4>$AD4,"A",IF($AC4<$AD4,"B","E")))
B5: Vencedor Oitava 7 x Vencedor Oitava 8 | C5: =TRIM(LEFT(B5,FIND(" x ",B5)-1)) -> Vencedor Oitava 7 | D5: =TRIM(MID(B5,FIND(" x ",B5)+3,100)) -> Vencedor Oitava 8 | E5: #x# | AC5: =IFERROR(VALUE(TRIM(LEFT($E5,SEARCH("x",$E5)-1))),"") | AD5: =IFERROR(VALUE(TRIM(MID($E5,SEARCH("x",$E5)+1,10))),"") | AE5: =IF(OR($AC5="",$AD5=""),"",IF($AC5>$AD5,"A",IF($AC5<$AD5,"B","E")))
H6: TOTAL | I6: {=SUMPRODUCT(--(UPPER(I2:I5)=$AE$2:$AE$5),--($AE$2:$AE$5<>""))+'MATA-MATA 16'!I10} -> 52 | J6: {=SUMPRODUCT(--(UPPER(J2:J5)=$AE$2:$AE$5),--($AE$2:$AE$5<>""))+'MATA-MATA 16'!J10} -> 51 | K6: {=SUMPRODUCT(--(UPPER(K2:K5)=$AE$2:$AE$5),--($AE$2:$AE$5<>""))+'MATA-MATA 16'!K10} -> 51 | L6: {=SUMPRODUCT(--(UPPER(L2:L5)=$AE$2:$AE$5),--($AE$2:$AE$5<>""))+'MATA-MATA 16'!L10} -> 53 | M6: {=SUMPRODUCT(--(UPPER(M2:M5)=$AE$2:$AE$5),--($AE$2:$AE$5<>""))+'MATA-MATA 16'!M10} -> 48 | N6: {=SUMPRODUCT(--(UPPER(N2:N5)=$AE$2:$AE$5),--($AE$2:$AE$5<>""))+'MATA-MATA 16'!N10} -> 49 | O6: {=SUMPRODUCT(--(UPPER(O2:O5)=$AE$2:$AE$5),--($AE$2:$AE$5<>""))+'MATA-MATA 16'!O10} -> 54 | P6: {=SUMPRODUCT(--(UPPER(P2:P5)=$AE$2:$AE$5),--($AE$2:$AE$5<>""))+'MATA-MATA 16'!P10} -> 57 | ... AB6: {=SUMPRODUCT(--(UPPER(AB2:AB5)=$AE$2:$AE$5),--($AE$2:$AE$5<>""))+'MATA-MATA 16'!AB10} -> 41

Sheet MATA-MATA 4
A1: DATAS | B1: CONFRONTOS | C1: TIME A | D1: TIME B | E1: PLACAR | F1: Penalti | G1: Prorrogação | I1: Alex | J1: Bonfim | K1: Christian | L1: Cleiton | M1: Daniel | N1: David | O1: Douglas | P1: Dunga | Q1: Felipe | R1: Gabriel | S1: Giliarde | T1: Gustavo | U1: Gustavo Lima | V1: Heitor | W1: Juninho | X1: Leonardo | Y1: Patrick | Z1: Rasta | AA1: Renan | AB1: Sanches | AC1: Gols A | AD1: Gols B | AE1: RESULTADO
B2: Vencedor Quarta 1 x Vencedor Quarta 2 | C2: =TRIM(LEFT(B2,FIND(" x ",B2)-1)) -> Vencedor Quarta 1 | D2: =TRIM(MID(B2,FIND(" x ",B2)+3,100)) -> Vencedor Quarta 2 | E2: #x# | AC2: =IFERROR(VALUE(TRIM(LEFT($E2,SEARCH("x",$E2)-1))),"") | AD2: =IFERROR(VALUE(TRIM(MID($E2,SEARCH("x",$E2)+1,10))),"") | AE2: =IF(OR($AC2="",$AD2=""),"",IF($AC2>$AD2,"A",IF($AC2<$AD2,"B","E")))
B3: Vencedor Quarta 3 x Vencedor Quarta 4 | C3: =TRIM(LEFT(B3,FIND(" x ",B3)-1)) -> Vencedor Quarta 3 | D3: =TRIM(MID(B3,FIND(" x ",B3)+3,100)) -> Vencedor Quarta 4 | E3: #x# | AC3: =IFERROR(VALUE(TRIM(LEFT($E3,SEARCH("x",$E3)-1))),"") | AD3: =IFERROR(VALUE(TRIM(MID($E3,SEARCH("x",$E3)+1,10))),"") | AE3: =IF(OR($AC3="",$AD3=""),"",IF($AC3>$AD3,"A",IF($AC3<$AD3,"B","E")))
H4: TOTAL | I4: {=SUMPRODUCT(--(UPPER(I2:I3)=$AE$2:$AE$3),--($AE$2:$AE$3<>""))+'MATA-MATA 8'!I6} -> 52 | J4: {=SUMPRODUCT(--(UPPER(J2:J3)=$AE$2:$AE$3),--($AE$2:$AE$3<>""))+'MATA-MATA 8'!J6} -> 51 | K4: {=SUMPRODUCT(--(UPPER(K2:K3)=$AE$2:$AE$3),--($AE$2:$AE$3<>""))+'MATA-MATA 8'!K6} -> 51 | L4: {=SUMPRODUCT(--(UPPER(L2:L3)=$AE$2:$AE$3),--($AE$2:$AE$3<>""))+'MATA-MATA 8'!L6} -> 53 | M4: {=SUMPRODUCT(--(UPPER(M2:M3)=$AE$2:$AE$3),--($AE$2:$AE$3<>""))+'MATA-MATA 8'!M6} -> 48 | N4: {=SUMPRODUCT(--(UPPER(N2:N3)=$AE$2:$AE$3),--($AE$2:$AE$3<>""))+'MATA-MATA 8'!N6} -> 49 | O4: {=SUMPRODUCT(--(UPPER(O2:O3)=$AE$2:$AE$3),--($AE$2:$AE$3<>""))+'MATA-MATA 8'!O6} -> 54 | P4: {=SUMPRODUCT(--(UPPER(P2:P3)=$AE$2:$AE$3),--($AE$2:$AE$3<>""))+'MATA-MATA 8'!P6} -> 57 | ... AB4: {=SUMPRODUCT(--(UPPER(AB2:AB3)=$AE$2:$AE$3),--($AE$2:$AE$3<>""))+'MATA-MATA 8'!AB6} -> 41

Sheet MATA-MATA 2
A1: DATAS | B1: CONFRONTOS | C1: TIME A | D1: TIME B | E1: PLACAR | F1: Penalti | G1: Prorrogação | I1: Alex | J1: Bonfim | K1: Christian | L1: Cleiton | M1: Daniel | N1: David | O1: Douglas | P1: Dunga | Q1: Felipe | R1: Gabriel | S1: Giliarde | T1: Gustavo | U1: Gustavo Lima | V1: Heitor | W1: Juninho | X1: Leonardo | Y1: Patrick | Z1: Rasta | AA1: Renan | AB1: Sanches | AC1: Gols A | AD1: Gols B | AE1: RESULTADO
B2: Vencedor Semifinal 1 x Vencedor Semifinal 2 | C2: =TRIM(LEFT(B2,FIND(" x ",B2)-1)) -> Vencedor Semifinal 1 | D2: =TRIM(MID(B2,FIND(" x ",B2)+3,100)) -> Vencedor Semifinal 2 | E2: #x# | AC2: =IFERROR(VALUE(TRIM(LEFT($E2,SEARCH("x",$E2)-1))),"") | AD2: =IFERROR(VALUE(TRIM(MID($E2,SEARCH("x",$E2)+1,10))),"") | AE2: =IF(OR($AC2="",$AD2=""),"",IF($AC2>$AD2,"A",IF($AC2<$AD2,"B","E")))
H3: TOTAL | I3: {=SUMPRODUCT(--(UPPER(I2:I2)=$AE$2:$AE$2),--($AE$2:$AE$2<>""))+'MATA-MATA 4'!I4} -> 52 | J3: {=SUMPRODUCT(--(UPPER(J2:J2)=$AE$2:$AE$2),--($AE$2:$AE$2<>""))+'MATA-MATA 4'!J4} -> 51 | K3: {=SUMPRODUCT(--(UPPER(K2:K2)=$AE$2:$AE$2),--($AE$2:$AE$2<>""))+'MATA-MATA 4'!K4} -> 51 | L3: {=SUMPRODUCT(--(UPPER(L2:L2)=$AE$2:$AE$2),--($AE$2:$AE$2<>""))+'MATA-MATA 4'!L4} -> 53 | M3: {=SUMPRODUCT(--(UPPER(M2:M2)=$AE$2:$AE$2),--($AE$2:$AE$2<>""))+'MATA-MATA 4'!M4} -> 48 | N3: {=SUMPRODUCT(--(UPPER(N2:N2)=$AE$2:$AE$2),--($AE$2:$AE$2<>""))+'MATA-MATA 4'!N4} -> 49 | O3: {=SUMPRODUCT(--(UPPER(O2:O2)=$AE$2:$AE$2),--($AE$2:$AE$2<>""))+'MATA-MATA 4'!O4} -> 54 | P3: {=SUMPRODUCT(--(UPPER(P2:P2)=$AE$2:$AE$2),--($AE$2:$AE$2<>""))+'MATA-MATA 4'!P4} -> 57 | ... AB3: {=SUMPRODUCT(--(UPPER(AB2:AB2)=$AE$2:$AE$2),--($AE$2:$AE$2<>""))+'MATA-MATA 4'!AB4} -> 41
